<?xml version="1.0" encoding="UTF-8"?>
<testng-results skipped="0" failed="4" ignored="0" total="7" passed="3">
  <reporter-output>
  </reporter-output>
  <suite name="Suite" duration-ms="105" started-at="2018-06-24T19:46:05Z" finished-at="2018-06-24T19:46:05Z">
    <groups>
      <group name="trigonometric">
        <method signature="CosTest.cosTest(double, double)[pri:0, instance:tests.CosTest@38cccef]" name="cosTest" class="tests.CosTest"/>
        <method signature="SinTest.cosTest(double, double)[pri:0, instance:tests.SinTest@5679c6c6]" name="cosTest" class="tests.SinTest"/>
      </group> <!-- trigonometric -->
    </groups>
    <test name="regression" duration-ms="105" started-at="2018-06-24T19:46:05Z" finished-at="2018-06-24T19:46:05Z">
      <class name="tests.CosTest">
        <test-method status="FAIL" signature="cosTest(double, double)[pri:0, instance:tests.CosTest@38cccef]" name="cosTest" duration-ms="21" started-at="2018-06-24T19:46:05Z" data-provider="valuesForCos" finished-at="2018-06-24T19:46:05Z">
          <params>
            <param index="0">
              <value>
                <![CDATA[1.5707963267948966]]>
              </value>
            </param>
            <param index="1">
              <value>
                <![CDATA[0.0]]>
              </value>
            </param>
          </params>
          <exception class="java.lang.AssertionError">
            <message>
              <![CDATA[expected [true] but found [false]]]>
            </message>
            <full-stacktrace>
              <![CDATA[java.lang.AssertionError: expected [true] but found [false]
at org.testng.Assert.fail(Assert.java:96)
at org.testng.Assert.failNotEquals(Assert.java:776)
at org.testng.Assert.assertTrue(Assert.java:44)
at org.testng.Assert.assertTrue(Assert.java:54)
at tests.CosTest.cosTest(CosTest.java:16)
at sun.reflect.NativeMethodAccessorImpl.invoke0(Native Method)
at sun.reflect.NativeMethodAccessorImpl.invoke(NativeMethodAccessorImpl.java:62)
at sun.reflect.DelegatingMethodAccessorImpl.invoke(DelegatingMethodAccessorImpl.java:43)
at java.lang.reflect.Method.invoke(Method.java:498)
at org.testng.internal.MethodInvocationHelper.invokeMethod(MethodInvocationHelper.java:124)
at org.testng.internal.Invoker.invokeMethod(Invoker.java:583)
at org.testng.internal.Invoker.invokeTestMethod(Invoker.java:719)
at org.testng.internal.Invoker.invokeTestMethods(Invoker.java:989)
at org.testng.internal.TestMethodWorker.invokeTestMethods(TestMethodWorker.java:125)
at org.testng.internal.TestMethodWorker.run(TestMethodWorker.java:109)
at org.testng.TestRunner.privateRun(TestRunner.java:648)
at org.testng.TestRunner.run(TestRunner.java:505)
at org.testng.SuiteRunner.runTest(SuiteRunner.java:455)
at org.testng.SuiteRunner.runSequentially(SuiteRunner.java:450)
at org.testng.SuiteRunner.privateRun(SuiteRunner.java:415)
at org.testng.SuiteRunner.run(SuiteRunner.java:364)
at org.testng.SuiteRunnerWorker.runSuite(SuiteRunnerWorker.java:52)
at org.testng.SuiteRunnerWorker.run(SuiteRunnerWorker.java:84)
at org.testng.TestNG.runSuitesSequentially(TestNG.java:1208)
at org.testng.TestNG.runSuitesSequentially(TestNG.java:1204)
at org.testng.TestNG.runSuitesLocally(TestNG.java:1137)
at org.testng.TestNG.runSuites(TestNG.java:1049)
at org.testng.TestNG.run(TestNG.java:1017)
at Runner.main(Runner.java:24)
]]>
            </full-stacktrace>
          </exception> <!-- java.lang.AssertionError -->
          <reporter-output>
          </reporter-output>
        </test-method> <!-- cosTest -->
        <test-method status="FAIL" signature="cosTest(double, double)[pri:0, instance:tests.CosTest@38cccef]" name="cosTest" duration-ms="1" started-at="2018-06-24T19:46:05Z" data-provider="valuesForCos" finished-at="2018-06-24T19:46:05Z">
          <params>
            <param index="0">
              <value>
                <![CDATA[0]]>
              </value>
            </param>
            <param index="1">
              <value>
                <![CDATA[1.0]]>
              </value>
            </param>
          </params>
          <exception class="java.lang.AssertionError">
            <message>
              <![CDATA[expected [true] but found [false]]]>
            </message>
            <full-stacktrace>
              <![CDATA[java.lang.AssertionError: expected [true] but found [false]
at org.testng.Assert.fail(Assert.java:96)
at org.testng.Assert.failNotEquals(Assert.java:776)
at org.testng.Assert.assertTrue(Assert.java:44)
at org.testng.Assert.assertTrue(Assert.java:54)
at tests.CosTest.cosTest(CosTest.java:16)
at sun.reflect.NativeMethodAccessorImpl.invoke0(Native Method)
at sun.reflect.NativeMethodAccessorImpl.invoke(NativeMethodAccessorImpl.java:62)
at sun.reflect.DelegatingMethodAccessorImpl.invoke(DelegatingMethodAccessorImpl.java:43)
at java.lang.reflect.Method.invoke(Method.java:498)
at org.testng.internal.MethodInvocationHelper.invokeMethod(MethodInvocationHelper.java:124)
at org.testng.internal.Invoker.invokeMethod(Invoker.java:583)
at org.testng.internal.Invoker.invokeTestMethod(Invoker.java:719)
at org.testng.internal.Invoker.invokeTestMethods(Invoker.java:989)
at org.testng.internal.TestMethodWorker.invokeTestMethods(TestMethodWorker.java:125)
at org.testng.internal.TestMethodWorker.run(TestMethodWorker.java:109)
at org.testng.TestRunner.privateRun(TestRunner.java:648)
at org.testng.TestRunner.run(TestRunner.java:505)
at org.testng.SuiteRunner.runTest(SuiteRunner.java:455)
at org.testng.SuiteRunner.runSequentially(SuiteRunner.java:450)
at org.testng.SuiteRunner.privateRun(SuiteRunner.java:415)
at org.testng.SuiteRunner.run(SuiteRunner.java:364)
at org.testng.SuiteRunnerWorker.runSuite(SuiteRunnerWorker.java:52)
at org.testng.SuiteRunnerWorker.run(SuiteRunnerWorker.java:84)
at org.testng.TestNG.runSuitesSequentially(TestNG.java:1208)
at org.testng.TestNG.runSuitesSequentially(TestNG.java:1204)
at org.testng.TestNG.runSuitesLocally(TestNG.java:1137)
at org.testng.TestNG.runSuites(TestNG.java:1049)
at org.testng.TestNG.run(TestNG.java:1017)
at Runner.main(Runner.java:24)
]]>
            </full-stacktrace>
          </exception> <!-- java.lang.AssertionError -->
          <reporter-output>
          </reporter-output>
        </test-method> <!-- cosTest -->
        <test-method status="FAIL" signature="cosTest(double, double)[pri:0, instance:tests.CosTest@38cccef]" name="cosTest" duration-ms="0" started-at="2018-06-24T19:46:05Z" data-provider="valuesForCos" finished-at="2018-06-24T19:46:05Z">
          <params>
            <param index="0">
              <value>
                <![CDATA[3.141592653589793]]>
              </value>
            </param>
            <param index="1">
              <value>
                <![CDATA[-1.0]]>
              </value>
            </param>
          </params>
          <exception class="java.lang.AssertionError">
            <message>
              <![CDATA[expected [true] but found [false]]]>
            </message>
            <full-stacktrace>
              <![CDATA[java.lang.AssertionError: expected [true] but found [false]
at org.testng.Assert.fail(Assert.java:96)
at org.testng.Assert.failNotEquals(Assert.java:776)
at org.testng.Assert.assertTrue(Assert.java:44)
at org.testng.Assert.assertTrue(Assert.java:54)
at tests.CosTest.cosTest(CosTest.java:16)
at sun.reflect.NativeMethodAccessorImpl.invoke0(Native Method)
at sun.reflect.NativeMethodAccessorImpl.invoke(NativeMethodAccessorImpl.java:62)
at sun.reflect.DelegatingMethodAccessorImpl.invoke(DelegatingMethodAccessorImpl.java:43)
at java.lang.reflect.Method.invoke(Method.java:498)
at org.testng.internal.MethodInvocationHelper.invokeMethod(MethodInvocationHelper.java:124)
at org.testng.internal.Invoker.invokeMethod(Invoker.java:583)
at org.testng.internal.Invoker.invokeTestMethod(Invoker.java:719)
at org.testng.internal.Invoker.invokeTestMethods(Invoker.java:989)
at org.testng.internal.TestMethodWorker.invokeTestMethods(TestMethodWorker.java:125)
at org.testng.internal.TestMethodWorker.run(TestMethodWorker.java:109)
at org.testng.TestRunner.privateRun(TestRunner.java:648)
at org.testng.TestRunner.run(TestRunner.java:505)
at org.testng.SuiteRunner.runTest(SuiteRunner.java:455)
at org.testng.SuiteRunner.runSequentially(SuiteRunner.java:450)
at org.testng.SuiteRunner.privateRun(SuiteRunner.java:415)
at org.testng.SuiteRunner.run(SuiteRunner.java:364)
at org.testng.SuiteRunnerWorker.runSuite(SuiteRunnerWorker.java:52)
at org.testng.SuiteRunnerWorker.run(SuiteRunnerWorker.java:84)
at org.testng.TestNG.runSuitesSequentially(TestNG.java:1208)
at org.testng.TestNG.runSuitesSequentially(TestNG.java:1204)
at org.testng.TestNG.runSuitesLocally(TestNG.java:1137)
at org.testng.TestNG.runSuites(TestNG.java:1049)
at org.testng.TestNG.run(TestNG.java:1017)
at Runner.main(Runner.java:24)
]]>
            </full-stacktrace>
          </exception> <!-- java.lang.AssertionError -->
          <reporter-output>
          </reporter-output>
        </test-method> <!-- cosTest -->
      </class> <!-- tests.CosTest -->
      <class name="tests.SinTest">
        <test-method status="PASS" signature="cosTest(double, double)[pri:0, instance:tests.SinTest@5679c6c6]" name="cosTest" duration-ms="1" started-at="2018-06-24T19:46:05Z" data-provider="valuesForSin" finished-at="2018-06-24T19:46:05Z">
          <params>
            <param index="0">
              <value>
                <![CDATA[1.5707963267948966]]>
              </value>
            </param>
            <param index="1">
              <value>
                <![CDATA[1.0]]>
              </value>
            </param>
          </params>
          <reporter-output>
          </reporter-output>
        </test-method> <!-- cosTest -->
        <test-method status="PASS" signature="cosTest(double, double)[pri:0, instance:tests.SinTest@5679c6c6]" name="cosTest" duration-ms="0" started-at="2018-06-24T19:46:05Z" data-provider="valuesForSin" finished-at="2018-06-24T19:46:05Z">
          <params>
            <param index="0">
              <value>
                <![CDATA[0]]>
              </value>
            </param>
            <param index="1">
              <value>
                <![CDATA[0.0]]>
              </value>
            </param>
          </params>
          <reporter-output>
          </reporter-output>
        </test-method> <!-- cosTest -->
        <test-method status="PASS" signature="cosTest(double, double)[pri:0, instance:tests.SinTest@5679c6c6]" name="cosTest" duration-ms="0" started-at="2018-06-24T19:46:05Z" data-provider="valuesForSin" finished-at="2018-06-24T19:46:05Z">
          <params>
            <param index="0">
              <value>
                <![CDATA[3.141592653589793]]>
              </value>
            </param>
            <param index="1">
              <value>
                <![CDATA[0.0]]>
              </value>
            </param>
          </params>
          <reporter-output>
          </reporter-output>
        </test-method> <!-- cosTest -->
        <test-method status="FAIL" signature="cosTest(double, double)[pri:0, instance:tests.SinTest@5679c6c6]" name="cosTest" duration-ms="1" started-at="2018-06-24T19:46:05Z" data-provider="valuesForSin" finished-at="2018-06-24T19:46:05Z">
          <params>
            <param index="0">
              <value>
                <![CDATA[0.5235987755982988]]>
              </value>
            </param>
            <param index="1">
              <value>
                <![CDATA[0.5]]>
              </value>
            </param>
          </params>
          <exception class="java.lang.AssertionError">
            <message>
              <![CDATA[expected [true] but found [false]]]>
            </message>
            <full-stacktrace>
              <![CDATA[java.lang.AssertionError: expected [true] but found [false]
at org.testng.Assert.fail(Assert.java:96)
at org.testng.Assert.failNotEquals(Assert.java:776)
at org.testng.Assert.assertTrue(Assert.java:44)
at org.testng.Assert.assertTrue(Assert.java:54)
at tests.SinTest.cosTest(SinTest.java:16)
at sun.reflect.NativeMethodAccessorImpl.invoke0(Native Method)
at sun.reflect.NativeMethodAccessorImpl.invoke(NativeMethodAccessorImpl.java:62)
at sun.reflect.DelegatingMethodAccessorImpl.invoke(DelegatingMethodAccessorImpl.java:43)
at java.lang.reflect.Method.invoke(Method.java:498)
at org.testng.internal.MethodInvocationHelper.invokeMethod(MethodInvocationHelper.java:124)
at org.testng.internal.Invoker.invokeMethod(Invoker.java:583)
at org.testng.internal.Invoker.invokeTestMethod(Invoker.java:719)
at org.testng.internal.Invoker.invokeTestMethods(Invoker.java:989)
at org.testng.internal.TestMethodWorker.invokeTestMethods(TestMethodWorker.java:125)
at org.testng.internal.TestMethodWorker.run(TestMethodWorker.java:109)
at org.testng.TestRunner.privateRun(TestRunner.java:648)
at org.testng.TestRunner.run(TestRunner.java:505)
at org.testng.SuiteRunner.runTest(SuiteRunner.java:455)
at org.testng.SuiteRunner.runSequentially(SuiteRunner.java:450)
at org.testng.SuiteRunner.privateRun(SuiteRunner.java:415)
at org.testng.SuiteRunner.run(SuiteRunner.java:364)
at org.testng.SuiteRunnerWorker.runSuite(SuiteRunnerWorker.java:52)
at org.testng.SuiteRunnerWorker.run(SuiteRunnerWorker.java:84)
at org.testng.TestNG.runSuitesSequentially(TestNG.java:1208)
at org.testng.TestNG.runSuitesSequentially(TestNG.java:1204)
at org.testng.TestNG.runSuitesLocally(TestNG.java:1137)
at org.testng.TestNG.runSuites(TestNG.java:1049)
at org.testng.TestNG.run(TestNG.java:1017)
at Runner.main(Runner.java:24)
]]>
            </full-stacktrace>
          </exception> <!-- java.lang.AssertionError -->
          <reporter-output>
          </reporter-output>
        </test-method> <!-- cosTest -->
      </class> <!-- tests.SinTest -->
    </test> <!-- regression -->
  </suite> <!-- Suite -->
  <suite name="Default Suite" duration-ms="0" started-at="2018-06-24T19:46:05Z" finished-at="2018-06-24T19:46:05Z">
    <groups>
    </groups>
  </suite> <!-- Default Suite -->
</testng-results>
